## Promise状态
实例对象中的属性`[PromiseState]`

1. pending -> resolved / fulfilled
2. pending -> rejected

只有以上两种，且一个Promise对象只能改变一次。

无论成功或失败，都会有一个结果数据，成功的数据被称为`value`，失败的被称为`reason`

#### PromiseResult
Promise实例对象的属性之一，保留了对象“成功/失败”的结果

#### Promise的执行流程
1. Promise构造函数: Promise(executor){}
   1. executor(): 执行器(resolve, reject) => {}
   2. resolve(value): 内部定义成功时我们调用(value) => {}
   3. reject(reason): 内部定义失败时我们调用(reason) => {}
2. Promise.prototype.then() :(onResolved, onRejected) => {}
   1. onResolved(value): 成功时的回调函数 (value) => {}
   2. onRejected(reason): 失败时的回调函数 (reason) => {}
3. Promise.prototype.catch(): (onRejected) => {}
   1. onRejected(reason): 失败时的回调函数 (reason) => {} 

`Promise.prototype.catch()`仅用于捕获失败信号，官方只是对`then(null,failureCallback)`进行封装而已

无论最后成功亦或者失败，都会生成一个新的`Promise`对象，适用于链式调用。

#### Promise.resolve
```js
let p1 = Promise.resolve(100);
console.log(p1);
```
该代码会直接生成一个状态为`fulfilled`的`Promise`对象，并且他的`PromiseResult`值为100

`resolve()`传入的值:
1. 非Promise对象: 状态设置为`fulfilled`
2. Promise对象: 状态设置为传入的Promise对象的状态

```js
let p1 = Promise.resolve(new Promise((resolve, reject)=>{
    // resolve();  p1的Promise对象状态也为成功
    // reject(); p1的Promise对象状态也为失败
}));
console.log(p1);
```
#### Promise.reject
```js
let p1 = Promise.reject(100);
console.log(p1);
```
该代码会直接生成一个状态为`rejected`的`Promise`对象，并且他的`PromiseResult`值为100

`reject()`传入的值:
1. 非Promise对象: 状态设置为`rejected`
2. Promise对象: 状态设置为`rejected`

```js
let p1 = Promise.reject(new Promise((resolve, reject)=>{
    // resolve();  p1的Promise对象状态也为失败
    // reject(); p1的Promise对象状态也为失败
}));
console.log(p1);
```

#### Promise.all
`Promise.all()`: (promises)=>{}

`promises`: 包含 n 个 `Promise` 的数组

返回一个新的Promise对象，其状态取决于传入的Promise数组，若所有Promise都是`resolved/fulfilled`则其结果也为`resolved/fulfilled`，否则为`rejected`。

```js
    let p1 = Promise.resolve(100);
    let p2 = Promise.resolve(100);
    let p3 = Promise.resolve(100);
    console.log(Promise.all([p1,p2,p3])) //新Promise的状态为成功，值为上述三个Promise组成的数组

    let p4 = Promise.resolve(100);
    let p5 = Promise.reject(200);
    let p6 = Promise.reject(100);
    console.log(Promise.all([p4,p5,p6])) //新Promise的状态为失败，值为第一个失败的Promise的值，也就是200
```

#### Promise.race
`Promise.race()`: (promises) => {}

`promises`: 包含 n 个 `Promise` 的数组

产生一个新的Promise对象，新的Promise对象的状态由第一个改变状态的Promise对象决定

使用场景: AJAX请求和超时回调，当AJAX请求在超时回调前完成，则显示AJAX请求结果，否则显示超时。

#### 链式调用
当Promise对象状态发生改变时，会调用所有指定状态的处理。

以下代码会在控制台打印OK并且抛出OK
```js
let p = new Promise((resolve, reject) => {
    resolve("OK");
}).then(value=>{console.log(value)}).then(value=>{alert(value)});
```

在链式调用中，最后`then()`会返回一个新的Promise，而新的Promise的`PromiseResult`值取决于`return`的结果
```js
let p = new Promise((resolve, reject) => {
    resolve("OK");
}).then(value=>{console.log(value);return value;}); //PromiseResult为value的值
```

在链式调用中，`then(value => {console.log(value),reason => {console.log(reason))`中,`value`和`reason`的值取决于`PromiseResult`，也就是说，倘若前一个`then()`没有`return value;`，那么下一个`then()`中的`value`将会是`undefined`
#### 改变状态与指定回调的顺序
1. 先执行`resolve()`，再指定回调
2. 先指定回调，再执行`resolve()`

若Promise对象的`executor()`中是同步任务，则先执行`resolve()`，再执行回调

否则，当`executor()`中是异步任务，则先指定回调，再执行`resolve()`

#### 异常穿透
即在链式调用末尾加上`catch()`用于捕获一连串`then()`中，可能出现的错误问题(e.g 空指针异常, 超出下标范围...)

```js
let arr = [1,2,3];
let p = new Promise((resolve, reject) => {
   resolve(4)
}).then(value => {
   console.log(111);
   return value;
}).then(value => {
   console.log(ar[value]);
   return value;
}).then(value => {
   console.log(333);
   return value;
}).catch(reason => {
   console.log("错误:"+reason)
});

// 输出
111
错误:ReferenceError: ar is not defined
```
上述代码中，由于`ar`变量不存在因此会报错，该报错会被`catch()`捕获并输出，一旦`then()`的链式调用中的一环出错，剩余的`then()`不会调用

#### 中断Promise链
如果我们想在某一环中断Promise链的调用，我们可以在该环处将Promise链状态变回`pending`即可。

```js
    let p = new Promise((resolve, reject) => {
        resolve(4)
    }).then(value => {
        console.log(111);
        return value;
    }).then(value => {
        console.log(222);
        return new Promise(()=>{}); //返回一个空的Promise对象即可，后续then不再执行
    }).then(value => {
        console.log(333);
        return value;
    })

```